Workbook

Sheet Capacity vs Delivery
A1: Capacity vs Delivery — FILTER · sprint-Bertha (Tue 20 Jan → Mon 02 Feb 2026)
A2: Team Composition (per Securly-PjM-Skills.md Part 2 — Filter India roster). Inactive members for this sprint window are shaded grey with a roster note.
A3: Name | B3: Role | C3: Function / Split | D3: Allocation (FTE) | E3: Seniority | F3: Employment | G3: Notes
A4: Shashank Tiwari | B4: Project Manager | C4: PM / Delivery | D4: 0 | E4: Lead | F4: FTE | G4: Not counted in delivery capacity
A5: Harsh Verma | B5: FE | C5: FrontEnd Architect (Angular) | D5: 1 | E5: Senior | F5: FTE
A6: Arun Thakur | B6: FE + Ext | C6: Angular / Extension | D6: 1 | E6: Medium | F6: FTE
A7: Harshada Kude | B7: FE | C7: Angular | D7: 1 | E7: Junior | F7: FTE
A8: Shailendra Singh | B8: FE | C8: Angular | D8: 1 | E8: Medium | F8: FTE
A9: Swaroop Chavhan | B9: FE + Ext | C9: Angular / Extension | D9: 1 | E9: Medium | F9: FTE
A10: Ashish Modak | B10: BE Architect | C10: Extension / Go / PHP | D10: 1 | E10: Senior | F10: FTE
A11: Prateek Fotedar | B11: BE (www) | C11: Go / PHP | D11: 1 | E11: Senior | F11: FTE
A12: Sagar Satpute | B12: BE (www) | C12: Go / PHP | D12: 1 | E12: Medium | F12: FTE
A13: Vaibhav Kumbhar | B13: BE | C13: Go / PHP | D13: 1 | E13: Medium | F13: FTE
A14: Ashish Temurnikar | B14: BE | C14: DNS / SPAC / Squid / Rust | D14: 1 | E14: Senior | F14: FTE
A15: Ravi Raj | B15: BE | C15: DNS / SPAC / Squid / Rust | D15: 1 | E15: Medium | F15: FTE
A16: Pratik Tiwari | B16: BE + Ext | C16: Extension / Go / Rust | D16: 1 | E16: Senior | F16: FTE
... A19: Ayesha Kamde | B19: QA | C19: Manual QA | D19: 1 | E19: Junior | F19: FTE
A20: Amol Mithari | B20: Auto QA Lead | C20: Team Lead — Auto QA / SDET | D20: 0 | E20: Lead | F20: FTE | G20: Joined team on 20-Feb-2026 — not part of this sprint
A21: Amit Shete | B21: Auto QA | C21: Pri. SDET | D21: 1 | E21: Senior | F21: FTE
A22: Rachit Mishra | B22: Auto QA | C22: SDET | D22: 1 | E22: Junior | F22: FTE
A23: Total FILTER allocation | D23: =SUM(D4:D22) | E23: FTE-equivalent heads available to FILTER
A25: Capacity Parameters (yellow cells are inputs — re-run the script after edits)
A26: Parameter | B26: Value | C26: Description
A27: Sprint length (working days) | B27: 10 | C27: FILTER 15-day sprint Tue → Mon. sprint-Bertha = 2026-01-20 → 2026-02-02.
A28: Company holidays in sprint | B28: 1 | C28: India calendar 2026 — 26-Jan: Republic Day
A29: Effective working days (sprint − company holidays) | B29: =B27-B28 | C29: Used as the per-person calendar for availability
A30: Hours per working day (nominal) | B30: 8 | C30: Standard working day
A31: Focus factor (productive fraction) | B31: 0.9 | C31: 90% — what SLT expects (sprint-analysis default)
A32: Misc buffer (meetings, scrums, code review, …) | B32: 0.2 | C32: 20% blanket reservation deducted from Available to get Net Available
A33: Effective hours per FTE per sprint | B33: =B29*B30*B31 | C33: =effective days × hrs/day × focus factor
A34: Allocated FTE on FILTER (active this sprint) | B34: 17 | C34: Headcount actually working this sprint (excludes joiners/leavers outside window)
A35: Ideal capacity for the sprint (hrs) | B35: =B33*B34 | C35: =effective hrs/FTE × allocated FTE
A36: Issue scope (Jira projects) | B36: FILTER, PTGM, FDSE | C36: Tickets pulled with `project in (FILTER, PTGM, FDSE) AND sprint = …` — FDSE: 11 · FILTER: 273 · PTGM: 21
A38: Capacity vs Actual Delivery — sprint-Bertha
A39: Metric | B39: Hours | C39: % of Ideal | D39: Rating | E39: Notes
A40: Actual Availability | B40: ='Per-person Delivery'!F19 | D40: =IF(C40="","",IF(C40>=0.85,"On Target",IF(C40>=0.7,"Below Target","Significantly Below"))) | E40: Sum of per-person availability (Ideal − leaves)
A41: Misc Buffer (20%) | B41: ='Per-person Delivery'!H19 | D41: =IF(C41="","",IF(C41>=0.85,"On Target",IF(C41>=0.7,"Below Target","Significantly Below"))) | E41: Reserved for meetings, scrums, code reviews
A42: Net Available (Available − Misc Buffer) | B42: ='Per-person Delivery'!I19 | D42: =IF(C42="","",IF(C42>=0.85,"On Target",IF(C42>=0.7,"Below Target","Significantly Below"))) | E42: Realistic delivery capacity — used as the denominator for Completed %
A43: Completed | B43: ='Per-person Delivery'!B19 | C43: =IFERROR(B43/B42,"") | D43: =IF(C43="","",IF(C43>=0.85,"On Target",IF(C43>=0.7,"Below Target","Significantly Below"))) | E43: Sum of in-sprint timeSpent (Completed bucket)
A44: Not Completed (Spillover) | B44: ='Per-person Delivery'!C19 | C44: =IFERROR(B44/B42,"") | D44: =IF(C44="","",IF(C44>=0.85,"On Target",IF(C44>=0.7,"Below Target","Significantly Below"))) | E44: Original estimate for spillover (carried into next sprint)
...

Sheet Per-person Delivery
A1: Assignee | B1: Completed (hrs) | C1: Not Completed (hrs) | D1: Removed (hrs) | E1: Efficiency | F1: Available (hrs) | G1: Leave Days (sprint) | H1: Misc Buffer 20% (hrs) | I1: Net Available (hrs)
A2: Harsh Verma | B2: 62 | C2: 0 | D2: 32 | E2: =IFERROR(B2/I2,"") | F2: 43.2 | G2: 3 | H2: =F2*0.2 | I2: =F2-H2
A3: Arun Thakur | B3: 14.5 | C3: 0.5 | D3: 0 | E3: =IFERROR(B3/I3,"") | F3: 36 | G3: 4 | H3: =F3*0.2 | I3: =F3-H3
A4: Harshada Kude | B4: 55.5 | C4: 0 | D4: 8 | E4: =IFERROR(B4/I4,"") | F4: 64.8 | G4: 0 | H4: =F4*0.2 | I4: =F4-H4
A5: Shailendra Singh | B5: 38 | C5: 0 | D5: 44 | E5: =IFERROR(B5/I5,"") | F5: 64.8 | G5: 0 | H5: =F5*0.2 | I5: =F5-H5
A6: Swaroop Chavhan | B6: 48 | C6: 0 | D6: 12 | E6: =IFERROR(B6/I6,"") | F6: 64.8 | G6: 0 | H6: =F6*0.2 | I6: =F6-H6
A7: Ashish Modak | B7: 42 | C7: 0 | D7: 0 | E7: =IFERROR(B7/I7,"") | F7: 64.8 | G7: 0 | H7: =F7*0.2 | I7: =F7-H7
A8: Prateek Fotedar | B8: 105.5 | C8: 0 | D8: 0 | E8: =IFERROR(B8/I8,"") | F8: 64.8 | G8: 0 | H8: =F8*0.2 | I8: =F8-H8
A9: Sagar Satpute | B9: 197 | C9: 0 | D9: 0 | E9: =IFERROR(B9/I9,"") | F9: 64.8 | G9: 0 | H9: =F9*0.2 | I9: =F9-H9
A10: Vaibhav Kumbhar | B10: 24 | C10: 0 | D10: 0 | E10: =IFERROR(B10/I10,"") | F10: 64.8 | G10: 0 | H10: =F10*0.2 | I10: =F10-H10
A11: Ashish Temurnikar | B11: 62 | C11: 0 | D11: 16 | E11: =IFERROR(B11/I11,"") | F11: 64.8 | G11: 0 | H11: =F11*0.2 | I11: =F11-H11
A12: Ravi Raj | B12: 88 | C12: 0 | D12: 12 | E12: =IFERROR(B12/I12,"") | F12: 64.8 | G12: 0 | H12: =F12*0.2 | I12: =F12-H12
A13: Pratik Tiwari | B13: 72 | C13: 0 | D13: 12 | E13: =IFERROR(B13/I13,"") | F13: 64.8 | G13: 0 | H13: =F13*0.2 | I13: =F13-H13
... A18: Rachit Mishra | B18: 48 | C18: 0 | D18: 0 | E18: =IFERROR(B18/I18,"") | F18: 64.8 | G18: 0 | H18: =F18*0.2 | I18: =F18-H18
A19: TOTAL | B19: =SUM(B2:B18) | C19: =SUM(C2:C18) | D19: =SUM(D2:D18) | E19: =IFERROR(B19/I19,"") | F19: =SUM(F2:F18) | G19: =SUM(G2:G18) | H19: =SUM(H2:H18) | I19: =SUM(I2:I18)

Sheet Completed
A1: Issue Type | B1: Issue key | C1: Summary | D1: Parent key | E1: Parent type | F1: Assignee | G1: Status | H1: Resolution | I1: Priority | J1: Created | K1: Resolved | L1: Updated | M1: Sprint | N1: Time Spent | O1: Original Est | P1: Project | Q1: Labels | R1: Blockers | S1: Added Mid-Sprint
A2: Debug | B2: FILTER-11747 | C2: Image Blur – NSFW Model Switch (InceptionV3 → MobileNetV2) | F2: Arun Thakur | G2: Closed | H2: Fixed | I2: P3 | J2: 46043 | K2: 46044 | L2: 46062 | M2: sprint-Bertha | N2: 8 | O2: 8 | P2: FILTER | Q2: unplanned-sprint | S2: YES
A3: Task | B3: FILTER-11787 | C3: Remove school.pepikutan.net - rammerhead from vector expansion config.json | F3: Arun Thakur | G3: Closed | I3: P3 | J3: 46045 | L3: 46128 | M3: sprint-Bertha | N3: 3 | O3: 3 | P3: FILTER | Q3: unplanned-sprint | S3: YES
A4: Escape Defect | B4: FILTER-7871 | C4: P1 Escalation-Shortcut SmartPAC bypass; --user-agent | Seattleschools | F4: Ashish Temurnikar | G4: Closed | H4: Expected behavior | I4: P1 | J4: 45758 | K4: 46041 | L4: 46062 | M4: sprint-Bertha | N4: 0 | O4: 0 | P4: FILTER | Q4: Reverified-2026, jira_added, jira_backlog, jira_closed_notify, jira_escalated, jira_in_progress, jira_open, jira_reopened, p1escalation, unplanned-sprint | S4: YES
A5: Escape Defect | B5: FILTER-11743 | C5: Restrict AI power mode in search engines setting is currently a configurable setting in policies | F5: Ayesha Kamde | G5: Done | H5: Done | I5: P3 | J5: 46042 | K5: 46055 | L5: 46127 | M5: sprint-Bertha | N5: 6 | O5: 0 | P5: FILTER | Q5: jira_added, jira_closed_notify, jira_done, jira_escalated, jira_p3, jira_qa_verified, unplanned-sprint | S5: YES
A6: Task | B6: FILTER-11695 | C6: Helping classroom team for PR review and Technical discussions | F6: Harsh Verma | G6: Closed | I6: P3 | J6: 46041 | L6: 46129 | M6: sprint-Bertha | N6: 4 | O6: 4 | P6: FILTER | Q6: unplanned-sprint | S6: YES
A7: Task | B7: FILTER-11696 | C7: Helping Home Team for the overall architecture of Parent Portal design Revamp and and AI Chat for their dashobard requirement | F7: Harsh Verma | G7: Closed | I7: P3 | J7: 46041 | L7: 46129 | M7: sprint-Bertha | N7: 24 | O7: 24 | P7: FILTER | Q7: unplanned-sprint | S7: YES
A8: Task | B8: FILTER-11698 | C8: Do a POC on CMS and its consumption in different products | F8: Harsh Verma | G8: Closed | I8: P3 | J8: 46041 | L8: 46129 | M8: sprint-Bertha | N8: 28 | O8: 40 | P8: FILTER | S8: YES
A9: Task | B9: FILTER-11770 | C9: Fix GitHub Action build issue | F9: Harsh Verma | G9: Closed | H9: Done | I9: P3 | J9: 46044 | K9: 46050 | L9: 46129 | M9: sprint-Bertha | N9: 6 | O9: 8 | P9: FILTER | Q9: unplanned-sprint | S9: YES
A10: Task | B10: FDSE-141 | C10: Cosume Label component | D10: FDSE-146 | E10: Epic | F10: Harshada Kude | G10: Resolved | H10: Fixed | I10: P3 | J10: 46013 | K10: 46044 | L10: 46045 | M10: sprint-Bertha | N10: 5.5 | O10: 8 | P10: FDSE | Q10: product-filter | S10: YES
A11: Task | B11: FILTER-11590 | C11: [sprox] unwrap handling in main.rs - main.rs modularisation part 3 | D11: FILTER-8230 | E11: Epic | F11: Pratik Tiwari | G11: Closed | I11: P2 | J11: 46027 | L11: 46128 | M11: sprint-Bertha | N11: 8 | O11: 8 | P11: FILTER | S11: YES
A12: Escape Defect | B12: FILTER-8535 | C12: P1 Escalation-Google search drag and drop bypass | F12: Pratik Tiwari | G12: Closed | H12: Cannot Reproduce | I12: P1 | J12: 45807 | K12: 46079 | L12: 46079 | M12: sprint-Bertha | N12: 24 | O12: 8 | P12: FILTER | Q12: Reverified-2025, jira_added, jira_backlog, jira_escalated, jira_qa_verified, p1escalation, unplanned-sprint | S12: YES
A13: Task | B13: FDSE-147 | C13: Datepicker Single Date and Date Range - UX enhancements, review comments | D13: FDSE-102 | E13: Epic | F13: Swaroop Chavhan | G13: Resolved | H13: Fixed | I13: P3 | J13: 46041 | K13: 46054 | L13: 46055 | M13: sprint-Bertha | N13: 32 | O13: 24 | P13: FDSE | Q13: product-filter | S13: YES
A14: QA | B14: FILTER-10858 | C14: QA - List of custom list (New API) | D14: FILTER-10835 | E14: Story | F14: Altamash Heroli | G14: QA Verified | I14: P3 | J14: 45982 | L14: 46035 | M14: sprint-Bertha | N14: 5 | O14: 5 | P14: FILTER | Q14: Capitalized-Feature
A15: QA | B15: FILTER-10861 | C15: QA - Get Resources of securly custom list (New API) | D15: FILTER-10835 | E15: Story | F15: Altamash Heroli | G15: QA Verified | I15: P3 | J15: 45982 | L15: 46031 | M15: sprint-Bertha | N15: 5 | O15: 4 | P15: FILTER | Q15: Capitalized-Feature
A16: QA | B16: FILTER-10864 | C16: Add/Update custom list (New API) | D16: FILTER-10835 | E16: Story | F16: Altamash Heroli | G16: QA Verified | I16: P3 | J16: 45982 | L16: 46031 | M16: sprint-Bertha | N16: 5 | O16: 4 | P16: FILTER | Q16: Capitalized-Feature
A17: QA | B17: FILTER-10867 | C17: QA - Delete custom list (New API) | D17: FILTER-10835 | E17: Story | F17: Altamash Heroli | G17: QA Verified | I17: P3 | J17: 45982 | L17: 46031 | M17: sprint-Bertha | N17: 5 | O17: 10 | P17: FILTER | Q17: Capitalized-Feature
A18: QA | B18: FILTER-10870 | C18: How to Handle sycing Error | D18: FILTER-10835 | E18: Story | F18: Altamash Heroli | G18: QA Verified | I18: P3 | J18: 45982 | L18: 46031 | M18: sprint-Bertha | N18: 5 | O18: 0 | P18: FILTER | Q18: Capitalized-Feature
A19: QA | B19: FILTER-10874 | C19: Link polices to custom list in case of update | D19: FILTER-10871 | E19: Story | F19: Altamash Heroli | G19: QA Verified | I19: P3 | J19: 45982 | L19: 46045 | M19: sprint-Bertha | N19: 3 | O19: 6 | P19: FILTER | Q19: Capitalized-Feature
A20: QA | B20: FILTER-10877 | C20: New Feature | Unlink polices to custom list in case of update | D20: FILTER-10871 | E20: Story | F20: Altamash Heroli | G20: QA Verified | I20: P3 | J20: 45982 | L20: 46045 | M20: sprint-Bertha | N20: 1 | O20: 6 | P20: FILTER | Q20: Capitalized-Feature
A21: QA | B21: FILTER-10881 | C21: New Feature | Add custom list (New API) | D21: FILTER-10878 | E21: Story | F21: Altamash Heroli | G21: QA Verified | I21: P3 | J21: 45982 | L21: 46045 | M21: sprint-Bertha | N21: 8 | O21: 10 | P21: FILTER | Q21: Capitalized-Feature
A22: QA | B22: FILTER-10884 | C22: New Feature | List of Policies (Might be existing API or New API) | D22: FILTER-10878 | E22: Story | F22: Altamash Heroli | G22: QA Verified | I22: P3 | J22: 45982 | L22: 46045 | M22: sprint-Bertha | N22: 1 | O22: 5 | P22: FILTER | Q22: Capitalized-Feature
A23: QA | B23: FILTER-10887 | C23: New Feature | Get custom list Details (New API) | D23: FILTER-10878 | E23: Story | F23: Altamash Heroli | G23: QA Verified | I23: P3 | J23: 45982 | L23: 46045 | M23: sprint-Bertha | N23: 3 | O23: 3 | P23: FILTER | Q23: Capitalized-Feature
A24: QA | B24: FILTER-10890 | C24: New Feature | Get custom list Resources (New API) | D24: FILTER-10878 | E24: Story | F24: Altamash Heroli | G24: QA Verified | I24: P3 | J24: 45982 | L24: 46045 | M24: sprint-Bertha | N24: 4 | O24: 5 | P24: FILTER | Q24: Capitalized-Feature
A25: QA | B25: FILTER-10893 | C25: New Feature | Get custom list Association (New API) | D25: FILTER-10878 | E25: Story | F25: Altamash Heroli | G25: QA Verified | I25: P3 | J25: 45982 | L25: 46045 | M25: sprint-Bertha | N25: 3 | O25: 3 | P25: FILTER | Q25: Capitalized-Feature
... A38: QA | B38: FILTER-11113 | C38: New Feature | Fetching allow/block list of policy | D38: FILTER-11098 | E38: Story | F38: Altamash Heroli | G38: QA Verified | I38: P3 | J38: 45992 | L38: 46049 | M38: sprint-Bertha | N38: 0.08 | O38: 2 | P38: FILTER | Q38: Capitalized-Feature
A39: QA | B39: FILTER-11209 | C39: QA - main.rs module separation part-2 | D39: FILTER-10743 | E39: Task | F39: Altamash Heroli | G39: Closed without action | I39: P3 | J39: 45994 | L39: 45999 | M39: sprint-Bertha | N39: 0 | O39: 0 | P39: FILTER
A40: QA | B40: FILTER-11281 | C40: QA - [sprox] SQS connection service implementation | D40: FILTER-10744 | E40: Task | F40: Altamash Heroli | G40: Closed without action | I40: P3 | J40: 45995 | L40: 45999 | M40: sprint-Bertha | N40: 0 | O40: 0 | P40: FILTER
A41: QA | B41: FILTER-11284 | C41: QA - [sprox] Td-Agent service implementation | D41: FILTER-10745 | E41: Task | F41: Altamash Heroli | G41: Closed without action | I41: P3 | J41: 45995 | L41: 45999 | M41: sprint-Bertha | N41: 0 | O41: 0 | P41: FILTER
A42: QA | B42: FILTER-11542 | C42: Manual QA Validation: Broker Stability and Log Audit (us-east-1 AL2) | D42: FILTER-11312 | E42: Escape Defect | F42: Altamash Heroli | G42: Closed without action | I42: P2 | J42: 46012 | L42: 46055 | M42: sprint-Bertha | N42: 0 | O42: 0 | P42: FILTER
A43: QA | B43: FILTER-11641 | C43: Manual QA Validation for Youtube Unrestricted mode | D43: FILTER-11638 | E43: Escape Defect | F43: Altamash Heroli | G43: Done | I43: P3 | J43: 46036 | L43: 46128 | M43: sprint-Bertha | N43: 1 | O43: 4 | P43: FILTER
A44: QA | B44: FILTER-11648 | C44: QA Task | P1 Escalation-Shortcut SmartPAC bypass; --user-agent | Seattleschools | D44: FILTER-7871 | E44: Escape Defect | F44: Altamash Heroli | G44: Closed without action | I44: P1 | J44: 46037 | L44: 46049 | M44: sprint-Bertha | N44: 0 | O44: 0 | P44: FILTER
A45: QA | B45: FILTER-11730 | C45: Manual QA task for retesting | D45: FILTER-11678 | E45: Defect | F45: Altamash Heroli | G45: Closed without action | I45: P0 | J45: 46042 | L45: 46042 | M45: sprint-Bertha | N45: 0 | O45: 0 | P45: FILTER
A46: QA | B46: FILTER-11738 | C46: QA Task for retest | D46: FILTER-11689 | E46: Defect | F46: Altamash Heroli | G46: QA Verified | I46: P1 | J46: 46042 | L46: 46065 | M46: sprint-Bertha | N46: 1 | O46: 1 | P46: FILTER | Q46: Capitalized-Feature
A47: QA | B47: FILTER-11739 | C47: QA task for retest | D47: FILTER-11690 | E47: Defect | F47: Altamash Heroli | G47: Done | I47: P1 | J47: 46042 | L47: 46065 | M47: sprint-Bertha | N47: 1.02 | O47: 1 | P47: FILTER | Q47: Capitalized-Feature
A48: Automation | B48: FILTER-10857 | C48: Automation - List of custom list (New API) | D48: FILTER-10835 | E48: Story | F48: Amit Shete | G48: Done | I48: P3 | J48: 45982 | L48: 46031 | M48: sprint-Bertha | N48: 8.5 | O48: 8 | P48: FILTER | Q48: Capitalized-Feature
A49: Automation | B49: FILTER-10860 | C49: Automation - Get Resources of securly custom list (New API) | D49: FILTER-10835 | E49: Story | F49: Amit Shete | G49: Done | I49: P3 | J49: 45982 | L49: 46031 | M49: sprint-Bertha | N49: 6 | O49: 5 | P49: FILTER | Q49: Capitalized-Feature
A50: Automation | B50: FILTER-10863 | C50: Add/Update custom list (New API) | D50: FILTER-10835 | E50: Story | F50: Amit Shete | G50: Done | I50: P3 | J50: 45982 | L50: 46031 | M50: sprint-Bertha | N50: 4.5 | O50: 5 | P50: FILTER | Q50: Capitalized-Feature
A51: Automation | B51: FILTER-10866 | C51: Automation - Delete custom list (New API) | D51: FILTER-10835 | E51: Story | F51: Amit Shete | G51: Done | I51: P3 | J51: 45982 | L51: 46031 | M51: sprint-Bertha | N51: 3.5 | O51: 4 | P51: FILTER | Q51: Capitalized-Feature
A52: Automation | B52: FILTER-10869 | C52: How to Handle sycing Error | D52: FILTER-10835 | E52: Story | F52: Amit Shete | G52: Done | I52: P3 | J52: 45982 | L52: 46056 | M52: sprint-Bertha | N52: 6 | O52: 6 | P52: FILTER | Q52: Capitalized-Feature
...

Sheet Not Completed
A1: Issue Type | B1: Issue key | C1: Summary | D1: Parent key | E1: Parent type | F1: Assignee | G1: Status | H1: Resolution | I1: Priority | J1: Created | K1: Resolved | L1: Updated | M1: Sprint | N1: Time Spent | O1: Original Est | P1: Project | Q1: Labels | R1: Blockers | S1: Added Mid-Sprint
A2: Code Review | B2: FILTER-11311 | C2: Review PR for the REL : REL-10348 | F2: Arun Thakur | G2: Backlog | I2: P3 | J2: 45995 | L2: 46056 | M2: sprint-Bertha | N2: 0 | O2: 0.25 | P2: FILTER
A3: Code Review | B3: FILTER-11327 | C3: Review PR for the REL : REL-10355 | F3: Arun Thakur | G3: Backlog | I3: P3 | J3: 45996 | L3: 46056 | M3: sprint-Bertha | N3: 0 | O3: 0.25 | P3: FILTER
A4: Code Review | B4: FILTER-11406 | C4: Review PR for the REL : REL-10361 | F4: Arun Thakur | G4: Backlog | I4: P3 | J4: 46001 | L4: 46056 | M4: sprint-Bertha | N4: 0 | O4: 0 | P4: FILTER
A5: Code Review | B5: FILTER-11063 | C5: Review PR for the REL : REL-10254 | F5: Harsh Verma | G5: Backlog | I5: P3 | J5: 45989 | L5: 46056 | M5: sprint-Bertha | N5: 0 | O5: 0 | P5: FILTER
A6: Code Review | B6: FILTER-11427 | C6: Review PR for the REL : REL-10316 | F6: Harsh Verma | G6: Backlog | I6: P3 | J6: 46002 | L6: 46056 | M6: sprint-Bertha | N6: 0 | O6: 0 | P6: FILTER
A7: Code Review | B7: FILTER-11303 | C7: Review PR for the REL : REL-10345 | F7: Pratik Tiwari | G7: Backlog | I7: P3 | J7: 45995 | L7: 46056 | M7: sprint-Bertha | N7: 0 | O7: 0 | P7: FILTER
A8: Code Review | B8: FILTER-11310 | C8: Review PR for the REL : REL-10321 | F8: Pratik Tiwari | G8: Backlog | I8: P3 | J8: 45995 | L8: 46056 | M8: sprint-Bertha | N8: 0 | O8: 0 | P8: FILTER
A9: Code Review | B9: FILTER-11404 | C9: Review PR for the REL : REL-10361 | F9: Pratik Tiwari | G9: Backlog | I9: P3 | J9: 46001 | L9: 46056 | M9: sprint-Bertha | N9: 0 | O9: 0 | P9: FILTER
A10: Code Review | B10: FILTER-11064 | C10: Review PR for the REL : REL-10254 | F10: Swaroop Chavhan | G10: Backlog | I10: P3 | J10: 45989 | L10: 46056 | M10: sprint-Bertha | N10: 0 | O10: 0 | P10: FILTER
A11: Code Review | B11: FILTER-11301 | C11: Review PR for the REL : REL-10345 | F11: Swaroop Chavhan | G11: Backlog | I11: P3 | J11: 45995 | L11: 46056 | M11: sprint-Bertha | N11: 0 | O11: 0 | P11: FILTER
A12: Code Review | B12: FILTER-11372 | C12: Review PR for the REL : REL-10198 | F12: Swaroop Chavhan | G12: Backlog | I12: P3 | J12: 46000 | L12: 46056 | M12: sprint-Bertha | N12: 0 | O12: 0 | P12: FILTER
A13: Code Review | B13: FILTER-11405 | C13: Review PR for the REL : REL-10361 | F13: Swaroop Chavhan | G13: Backlog | I13: P3 | J13: 46001 | L13: 46056 | M13: sprint-Bertha | N13: 0 | O13: 0 | P13: FILTER

Sheet Removed
A1: Issue Type | B1: Issue key | C1: Summary | D1: Parent key | E1: Parent type | F1: Assignee | G1: Status | H1: Resolution | I1: Priority | J1: Created | K1: Resolved | L1: Updated | M1: Sprint | N1: Time Spent | O1: Original Est | P1: Project | Q1: Labels | R1: Blockers | S1: Added Mid-Sprint
A2: Task | B2: FILTER-11697 | C2: Extension of FILTER-11605 | F2: Harsh Verma | G2: In Progress | I2: P3 | J2: 46041 | L2: 46139 | M2: sprint-Bertha | N2: 0 | O2: 24 | P2: FILTER | Q2: unplanned-sprint | S2: YES
A3: Task | B3: FDSE-145 | C3: Side Drawer Design Changes | D3: FDSE-109 | E3: Epic | F3: Harshada Kude | G3: Open | I3: P3 | J3: 46038 | L3: 46042 | M3: sprint-Bertha | N3: 0 | O3: 8 | P3: FDSE | S3: YES
A4: Task | B4: FILTER-11713 | C4: [sprox] Securly cookie creation logic implementation | D4: FILTER-8230 | E4: Epic | F4: Ashish Temurnikar | G4: Closed | I4: P3 | J4: 46041 | L4: 46086 | M4: sprint-Bertha | N4: 20 | O4: 8 | P4: FILTER
A5: Defect | B5: FILTER-9299 | C5: NewFeatureBug: SPAC/DNS. Posts on X.com are getting logged twice. One as post and One as search. | F5: Ashish Temurnikar | G5: Reopened | H5: Fixed | I5: P2 | J5: 45861 | K5: 45863 | L5: 46083 | M5: sprint-Bertha | N5: 18 | O5: 8 | P5: FILTER
A6: Task | B6: FDSE-142 | C6: Dependabot issue fixes | F6: Harsh Verma | G6: Closed | I6: P3 | J6: 46027 | L6: 46084 | M6: sprint-Bertha | N6: 5 | O6: 8 | P6: FDSE | Q6: product-filter
A7: Task | B7: FILTER-10900 | C7: [Dependabot issues]Upgrade jspdf-autotable npm library to latest version (5.0) | F7: Harshada Kude | G7: Closed | I7: P3 | J7: 45982 | L7: 46084 | M7: sprint-Bertha | N7: 16 | O7: 0 | P7: FILTER
A8: Task | B8: FILTER-11711 | C8: [sprox] Changes certificate logic to be backward compatible with existing redis DB24 | D8: FILTER-8230 | E8: Epic | F8: Pratik Tiwari | G8: Closed | H8: Fixed | I8: P2 | J8: 46041 | K8: 46063 | L8: 46084 | M8: sprint-Bertha | N8: 12 | O8: 12 | P8: FILTER
A9: Task | B9: FILTER-9275 | C9: [SPAC] Moving cluster & proxy URL to globals | F9: Ravi Raj | G9: Closed | I9: P2 | J9: 45860 | L9: 46084 | M9: sprint-Bertha | N9: 20 | O9: 12 | P9: FILTER
A10: Defect | B10: FILTER-11581 | C10: NewFeatureBug: SupportTool Customlist API. Name field can be saved with spaces at start and end. Add/Update | F10: Sagar Satpute | G10: Closed without action | I10: P3 | J10: 46027 | L10: 46058 | M10: sprint-Bertha | N10: 0 | O10: 0 | P10: FILTER | Q10: unplanned-sprint
A11: Task | B11: FDSE-112 | C11: Implementation of Button bars as per the design | D11: FDSE-111 | E11: Epic | F11: Shailendra Singh | G11: Resolved | H11: Fixed | I11: P3 | J11: 45981 | K11: 46062 | L11: 46062 | M11: sprint-Bertha | N11: 24 | O11: 20 | P11: FDSE | Q11: product-filter
A12: Task | B12: FDSE-123 | C12: Simple search component implementation without chip and without auto-complete | D12: FDSE-122 | E12: Epic | F12: Shailendra Singh | G12: Resolved | I12: P3 | J12: 45995 | L12: 46064 | M12: sprint-Bertha | N12: 4 | O12: 24 | P12: FDSE | Q12: Capitalized-Feature, product-filter
A13: Task | B13: FDSE-126 | C13: Analysis - Search without chip but with auto-complete component implementation | D13: FDSE-174 | E13: Epic | F13: Swaroop Chavhan | G13: Resolved | I13: P3 | J13: 45995 | L13: 46127 | M13: sprint-Bertha | N13: 12 | O13: 12 | P13: FDSE | Q13: Capitalized-Feature, product-filter

Sheet P1 Escalation
A1: P1 Escalation — FILTER · sprint-Bertha (2026-01-20 → 2026-02-02)
A2: sprint-Bertha tickets where Issue Type = Escape Defect AND Priority = P1 AND summary contains 'P1 Escalation' (regardless of bucket). Total = 13.
A4: Issue Type | B4: Issue key | C4: Summary | D4: Parent key | E4: Parent type | F4: Assignee | G4: Status | H4: Resolution | I4: Priority | J4: Created | K4: Resolved | L4: Updated | M4: Sprint | N4: Time Spent | O4: Original Est | P4: Project | Q4: Labels | R4: Blockers | S4: Bucket
A5: Escape Defect | B5: FILTER-11610 | C5: P1 Escalation-CORs Errors at BlueBeam and Boomerang S3 Amazon domains | St. Vrain | F5: Ramani Cheruvu | G5: In Progress | H5: Fixed | I5: P1 | J5: 46030 | K5: 46049 | L5: 46139 | M5: sprint-Bertha | N5: 0 | O5: 0 | P5: FILTER | Q5: Reverified-2026, jira_added, jira_backlog, jira_escalated, jira_in_progress, jira_open, jira_p1, jira_reopened, p1escalation, unplanned-sprint, zendesk_enterprise | S5: Removed
A6: Escape Defect | B6: FILTER-10237 | C6: P1 escalation-Crextn-specific Bypass using upgraded credentials | F6: Ashish Modak | G6: Release in Progress | H6: Fixed | I6: P1 | J6: 45926 | K6: 45981 | L6: 46056 | M6: sprint-Bertha | N6: 6 | O6: 6 | P6: FILTER | Q6: Reverified-2025, jira_added, jira_backlog, jira_escalated, jira_in_progress, p1escalation, unplanned-sprint | S6: Completed
A7: Escape Defect | B7: FILTER-7871 | C7: P1 Escalation-Shortcut SmartPAC bypass; --user-agent | Seattleschools | F7: Ashish Temurnikar | G7: Closed | H7: Expected behavior | I7: P1 | J7: 45758 | K7: 46041 | L7: 46062 | M7: sprint-Bertha | N7: 0 | O7: 0 | P7: FILTER | Q7: Reverified-2026, jira_added, jira_backlog, jira_closed_notify, jira_escalated, jira_in_progress, jira_open, jira_reopened, p1escalation, unplanned-sprint | S7: Completed
A8: Escape Defect | B8: FILTER-8535 | C8: P1 Escalation-Google search drag and drop bypass | F8: Pratik Tiwari | G8: Closed | H8: Cannot Reproduce | I8: P1 | J8: 45807 | K8: 46079 | L8: 46079 | M8: sprint-Bertha | N8: 24 | O8: 8 | P8: FILTER | Q8: Reverified-2025, jira_added, jira_backlog, jira_escalated, jira_qa_verified, p1escalation, unplanned-sprint | S8: Completed
A9: Escape Defect | B9: FILTER-10034 | C9: P1 Escalation-YouTube blocked while doing a Google Search | F9: Shashank Tiwari | G9: Done | H9: Fixed | I9: P1 | J9: 45912 | K9: 45985 | L9: 46128 | M9: sprint-Bertha | N9: 5 | O9: 5 | P9: FILTER | Q9: jira_added, jira_closed_notify, jira_confirmation, jira_done, jira_escalated, jira_in_progress, jira_open, jira_p1, jira_p3, jira_qa_verified, jira_reopened, p1escalation, unplanned-sprint, zendesk_org_at_risk | S9: Removed
A10: Escape Defect | B10: FILTER-10392 | C10: P1 Escalation-YouTube Videos play in Gmail even when blocked in policy | Downingtown | F10: Shashank Tiwari | G10: Done | H10: Fixed | I10: P1 | J10: 45940 | K10: 46063 | L10: 46119 | M10: sprint-Bertha | N10: 16 | O10: 16 | P10: FILTER | Q10: Reverified-2025, jira_added, jira_backlog, jira_closed_notify, jira_escalated, jira_in_progress, jira_qa_verified, jira_reopened, p1escalation, unplanned-sprint | S10: Removed
A11: Escape Defect | B11: FILTER-11047 | C11: P1 Escalation-Filter bypass using Chrome://chrome-signin | Edmonds | F11: Shashank Tiwari | G11: Done | H11: Fixed | I11: P1 | J11: 45987 | K11: 46049 | L11: 46132 | M11: sprint-Bertha | N11: 17 | O11: 0 | P11: FILTER | Q11: Reverified-2025, jira_added, jira_backlog, jira_closed_notify, jira_done, jira_escalated, jira_in_progress, jira_open, jira_qa_verified, p1escalation | S11: Completed
A12: Escape Defect | B12: FILTER-11443 | C12: P1 Escalation-Chrome extension bypass using Omada DNS | F12: Shashank Tiwari | G12: Done | H12: Fixed | I12: P1 | J12: 46006 | K12: 46043 | L12: 46119 | M12: sprint-Bertha | N12: 16 | O12: 16 | P12: FILTER | Q12: jira_added, jira_closed_notify, jira_done, jira_escalated, jira_p1, zendesk_enterprise | S12: Removed
A13: Escape Defect | B13: FILTER-11557 | C13: P1 Escalation-Copy & Paste movie script into search bar breaks extension | F13: Shashank Tiwari | G13: Done | H13: Fixed | I13: P1 | J13: 46013 | K13: 46038 | L13: 46119 | M13: sprint-Bertha | N13: 10 | O13: 12 | P13: FILTER | Q13: Reverified-2026, jira_added, jira_backlog, jira_done, jira_escalated, jira_in_progress, jira_open, jira_p1, jira_qa_verified, jira_reopened, p1escalation, unplanned-sprint | S13: Completed
A14: Escape Defect | B14: FILTER-11644 | C14: P1 Escalation-Image side bar is leaking inappropriate images on iOS | F14: Shashank Tiwari | G14: Done | H14: Fixed | I14: P1 | J14: 46036 | K14: 46051 | L14: 46118 | M14: sprint-Bertha | N14: 17 | O14: 0 | P14: FILTER | Q14: jira_added, jira_closed_notify, jira_done, jira_escalated, jira_p1, zendesk_enterprise | S14: Completed
A15: Escape Defect | B15: FILTER-11654 | C15: P1 Escalation-Crextn blocking issue with Google Workspace apps | D15: FILTER-4326 | E15: Epic | F15: Shashank Tiwari | G15: QA Verified | H15: Done | I15: P1 | J15: 46037 | K15: 46118 | L15: 46140 | M15: sprint-Bertha | N15: 0 | O15: 0 | P15: FILTER | Q15: jira_added, jira_escalated, jira_in_progress, jira_open, jira_p1, jira_qa_verified, jira_resolved | S15: Removed
A16: Escape Defect | B16: FILTER-11680 | C16: P1 Escalation-[PageScan] SPAC Changes for better coverage | F16: Shashank Tiwari | G16: Done | H16: Fixed | I16: P1 | J16: 46038 | K16: 46043 | L16: 46090 | M16: sprint-Bertha | N16: 14 | O16: 0 | P16: FILTER | Q16: Reverified-2026, p1escalation, unplanned-sprint | S16: Completed
A17: Escape Defect | B17: FILTER-11777 | C17: P1 Escalation-Google search overloading/breaking chrome extension | F17: Shashank Tiwari | G17: Closed | H17: Duplicate | I17: P1 | J17: 46044 | K17: 46049 | L17: 46063 | M17: sprint-Bertha | N17: 0 | O17: 0 | P17: FILTER | Q17: Reverified-2026, jira_added, jira_backlog, jira_closed_notify, jira_escalated, p1escalation, unplanned-sprint | S17: Completed
